Workbook
Name StartYear: Inputs!$B$6
Name IraStartAge: Inputs!$D$4
Name CarolStartAge: Inputs!$D$5
Name StartAfterTax: Inputs!$B$9
Name StartIRA: Inputs!$B$10
Name StartRoth: Inputs!$B$11
Name SSMonthly: Inputs!$B$14
Name SSAnnual: Inputs!$D$14
Name StartExpenses: Inputs!$B$15
Name ExpenseInflation: Inputs!$B$18
Name SSCOLA: Inputs!$B$19
Name ReturnAfterTax: Inputs!$B$20
Name ReturnIRA: Inputs!$B$21
Name ReturnRoth: Inputs!$B$22
Name DiscountRate: Inputs!$B$23
Name StdDeduction: Inputs!$B$28
Name TaxBracketInflation: Inputs!$B$29
Name ILTaxRate: Inputs!$B$30
Name CapGainsPct: Inputs!$B$31
Name NIITThreshold: Inputs!$B$32
Name MAGI2024: Inputs!$B$35
Name MAGI2025: Inputs!$B$36
Name DeathAge: Inputs!$B$39
Name SurvivorSS: Inputs!$B$40
Name StdDeductionSingle: Inputs!$B$45
Name NIITThresholdSingle: Inputs!$B$46
Name HeirTaxRate: Inputs!$P$6
Name RothConvTable: Inputs!$F$5:$G$34
Name OtherIncomeTable: Inputs!$I$5:$J$34
Name DiscretionaryTable: Inputs!$L$5:$M$34
Name RMDTable: Inputs!$A$50:$B$93
Name IRMAATableMFJ: Inputs!$D$50:$E$55
Name IRMAATableSingle: Inputs!$G$50:$H$55
Name IRMAA_MFJ_Thresh1: Inputs!$D$50
Name IRMAA_MFJ_Thresh2: Inputs!$D$51
Name IRMAA_MFJ_Thresh3: Inputs!$D$52
Name IRMAA_MFJ_Thresh4: Inputs!$D$53
Name IRMAA_MFJ_Thresh5: Inputs!$D$54
Name IRMAA_MFJ_Cost1: Inputs!$E$50
Name IRMAA_MFJ_Cost2: Inputs!$E$51
Name IRMAA_MFJ_Cost3: Inputs!$E$52
Name IRMAA_MFJ_Cost4: Inputs!$E$53
Name IRMAA_MFJ_Cost5: Inputs!$E$54
Name IRMAA_MFJ_Cost6: Inputs!$E$55
Name IRMAA_Single_Thresh1: Inputs!$G$50
Name IRMAA_Single_Thresh2: Inputs!$G$51
Name IRMAA_Single_Thresh3: Inputs!$G$52
Name IRMAA_Single_Thresh4: Inputs!$G$53
Name IRMAA_Single_Thresh5: Inputs!$G$54
Name IRMAA_Single_Cost1: Inputs!$H$50
Name IRMAA_Single_Cost2: Inputs!$H$51
Name IRMAA_Single_Cost3: Inputs!$H$52
Name IRMAA_Single_Cost4: Inputs!$H$53
Name IRMAA_Single_Cost5: Inputs!$H$54
Name IRMAA_Single_Cost6: Inputs!$H$55
Name LowRiskReturn: Inputs!$P$9
Name ModRiskReturn: Inputs!$P$10
Name HighRiskReturn: Inputs!$P$11
Name LowRiskTarget: Inputs!$P$12
Name ModRiskTarget: Inputs!$P$13

Sheet Inputs
A1: RETIREMENT PLANNING MODEL - IRA & CAROL
A3: PERSONAL INFORMATION | F3: ROTH CONVERSIONS | I3: OTHER INCOME | L3: DISCRETIONARY W/D | O3: HEIR TAX PARAMETERS
A4: Ira's Birth Date: | B4: Feb 17, 1955 | C4: Age in 2026: | D4: 71 | F4: Year | G4: Amount | I4: Year | J4: Amount | L4: Year | M4: Amount | O4: Heirs' Fed Tax Rate: | P4: 0.37
A5: Carol's Birth Date: | B5: Jul 17, 1954 | C5: Age in 2026: | D5: 72 | F5: =StartYear+0 | G5: 700000 | I5: =StartYear+0 | J5: 0 | L5: =StartYear+0 | M5: 0 | O5: Heirs' State Tax Rate: | P5: 0.0495
A6: Starting Year: | B6: 2026 | F6: =StartYear+1 | G6: 700000 | I6: =StartYear+1 | J6: 0 | L6: =StartYear+1 | M6: 0 | O6: Combined Heir Rate: | P6: =P4+P5
F7: =StartYear+2 | G7: 0 | I7: =StartYear+2 | J7: 0 | L7: =StartYear+2 | M7: 0
A8: STARTING ACCOUNT BALANCES | F8: =StartYear+3 | G8: 0 | I8: =StartYear+3 | J8: 0 | L8: =StartYear+3 | M8: 0 | O8: RISK ALLOCATION
A9: Joint After-Tax Account: | B9: 474000 | F9: =StartYear+4 | G9: 0 | I9: =StartYear+4 | J9: 0 | L9: =StartYear+4 | M9: 0 | O9: Low Risk Return: | P9: 0.04
A10: Combined Traditional IRA: | B10: 6121000 | F10: =StartYear+5 | G10: 0 | I10: =StartYear+5 | J10: 0 | L10: =StartYear+5 | M10: 0 | O10: Moderate Risk Return: | P10: 0.06
A11: Combined Roth IRA: | B11: 2612000 | F11: =StartYear+6 | G11: 0 | I11: =StartYear+6 | J11: 0 | L11: =StartYear+6 | M11: 0 | O11: High Risk Return: | P11: 0.08
F12: =StartYear+7 | G12: 0 | I12: =StartYear+7 | J12: 0 | L12: =StartYear+7 | M12: 0 | O12: Low Risk Target $: | P12: 474000
A13: SOCIAL SECURITY | F13: =StartYear+8 | G13: 0 | I13: =StartYear+8 | J13: 0 | L13: =StartYear+8 | M13: 0 | O13: Moderate Risk Target $: | P13: 6121000
A14: Monthly (2026): | B14: 5800 | C14: Annual: | D14: =B14*12 | F14: =StartYear+9 | G14: 0 | I14: =StartYear+9 | J14: 0 | L14: =StartYear+9 | M14: 0 | O14: High Risk Target $: | P14: (Remainder)
A15: Starting Annual Expenses: | B15: 180000 | F15: =StartYear+10 | G15: 0 | I15: =StartYear+10 | J15: 0 | L15: =StartYear+10 | M15: 0
F16: =StartYear+11 | G16: 0 | I16: =StartYear+11 | J16: 0 | L16: =StartYear+11 | M16: 0 | O16: Use Blended Returns: | P16: No | Q16: (Yes/No)
A17: RATES & ASSUMPTIONS | F17: =StartYear+12 | G17: 0 | I17: =StartYear+12 | J17: 0 | L17: =StartYear+12 | M17: 0
A18: Expense Inflation Rate: | B18: 0.03 | F18: =StartYear+13 | G18: 0 | I18: =StartYear+13 | J18: 0 | L18: =StartYear+13 | M18: 0
A19: Social Security COLA: | B19: 0.025 | F19: =StartYear+14 | G19: 0 | I19: =StartYear+14 | J19: 0 | L19: =StartYear+14 | M19: 0
A20: After-Tax Account Return: | B20: 0.04 | F20: =StartYear+15 | G20: 0 | I20: =StartYear+15 | J20: 0 | L20: =StartYear+15 | M20: 0
A21: Traditional IRA Return: | B21: 0.06 | F21: =StartYear+16 | G21: 0 | I21: =StartYear+16 | J21: 0 | L21: =StartYear+16 | M21: 0
A22: Roth IRA Return: | B22: 0.08 | F22: =StartYear+17 | G22: 0 | I22: =StartYear+17 | J22: 0 | L22: =StartYear+17 | M22: 0
A23: Discount Rate (for PV): | B23: 0.03 | F23: =StartYear+18 | G23: 0 | I23: =StartYear+18 | J23: 0 | L23: =StartYear+18 | M23: 0
F24: =StartYear+19 | G24: 0 | I24: =StartYear+19 | J24: 0 | L24: =StartYear+19 | M24: 0
A25: TAX PARAMETERS | F25: =StartYear+20 | G25: 0 | I25: =StartYear+20 | J25: 0 | L25: =StartYear+20 | M25: 0
A26: Standard Deduction (2024 base): | B26: 29200 | F26: =StartYear+21 | G26: 0 | I26: =StartYear+21 | J26: 0 | L26: =StartYear+21 | M26: 0
A27: Senior Bonus (both 65+): | B27: 3100 | F27: =StartYear+22 | G27: 0 | I27: =StartYear+22 | J27: 0 | L27: =StartYear+22 | M27: 0
A28: Total Std Deduction (base): | B28: =B26+B27 | F28: =StartYear+23 | G28: 0 | I28: =StartYear+23 | J28: 0 | L28: =StartYear+23 | M28: 0
A29: Tax Bracket Inflation: | B29: 0.025 | F29: =StartYear+24 | G29: 0 | I29: =StartYear+24 | J29: 0 | L29: =StartYear+24 | M29: 0
A30: IL State Tax Rate: | B30: 0.0495 | F30: =StartYear+25 | G30: 0 | I30: =StartYear+25 | J30: 0 | L30: =StartYear+25 | M30: 0
A31: Cap Gains % of After-Tax: | B31: 0.75 | F31: =StartYear+26 | G31: 0 | I31: =StartYear+26 | J31: 0 | L31: =StartYear+26 | M31: 0
A32: NIIT Threshold (2024 base): | B32: 250000 | F32: =StartYear+27 | G32: 0 | I32: =StartYear+27 | J32: 0 | L32: =StartYear+27 | M32: 0
F33: =StartYear+28 | G33: 0 | I33: =StartYear+28 | J33: 0 | L33: =StartYear+28 | M33: 0
A34: IRMAA - PRIOR YEAR MAGI | F34: =StartYear+29 | G34: 0 | I34: =StartYear+29 | J34: 0 | L34: =StartYear+29 | M34: 0
A35: 2024 MAGI (for 2026 IRMAA): | B35: 600000
A36: 2025 MAGI (for 2027 IRMAA): | B36: 600000
A38: SURVIVOR SCENARIO
A39: Ira's Death Age (blank=none): | C39: (e.g., 85)
A40: Survivor SS (Monthly, 2026): | B40: 3860 | C40: (escalates to death year)
A42: SINGLE FILER PARAMETERS
A43: Std Deduction (Single, 2024): | B43: 14600
...

Sheet Projections
A1: Year | B1: =StartYear | C1: =B1+1 | D1: =C1+1 | E1: =D1+1 | F1: =E1+1 | G1: =F1+1 | H1: =G1+1 | I1: =H1+1 | J1: =I1+1 | ... AE1: =AD1+1
A2: Ira Age | B2: =IraStartAge | C2: =B2+1 | D2: =C2+1 | E2: =D2+1 | F2: =E2+1 | G2: =F2+1 | H2: =G2+1 | I2: =H2+1 | J2: =I2+1 | ... AE2: =AD2+1
A3: Carol Age | B3: =CarolStartAge | C3: =B3+1 | D3: =C3+1 | E3: =D3+1 | F3: =E3+1 | G3: =F3+1 | H3: =G3+1 | I3: =H3+1 | J3: =I3+1 | ... AE3: =AD3+1
A4: Ira Alive? | B4: =IF(DeathAge="",TRUE,B2<DeathAge) | C4: =IF(DeathAge="",TRUE,C2<DeathAge) | D4: =IF(DeathAge="",TRUE,D2<DeathAge) | E4: =IF(DeathAge="",TRUE,E2<DeathAge) | F4: =IF(DeathAge="",TRUE,F2<DeathAge) | G4: =IF(DeathAge="",TRUE,G2<DeathAge) | H4: =IF(DeathAge="",TRUE,H2<DeathAge) | I4: =IF(DeathAge="",TRUE,I2<DeathAge) | ... AE4: =IF(DeathAge="",TRUE,AE2<DeathAge)
A6: BEGINNING BALANCES
A7: After-Tax | B7: =StartAfterTax | C7: =B50 | D7: =C50 | E7: =D50 | F7: =E50 | G7: =F50 | H7: =G50 | I7: =H50 | J7: =I50 | ... AE7: =AD50
A8: Traditional IRA | B8: =StartIRA | C8: =B51 | D8: =C51 | E8: =D51 | F8: =E51 | G8: =F51 | H8: =G51 | I8: =H51 | J8: =I51 | ... AE8: =AD51
A9: Roth IRA | B9: =StartRoth | C9: =B52 | D9: =C52 | E9: =D52 | F9: =E52 | G9: =F52 | H9: =G52 | I9: =H52 | J9: =I52 | ... AE9: =AD52
A10: Total | B10: =B7+B8+B9 | C10: =C7+C8+C9 | D10: =D7+D8+D9 | E10: =E7+E8+E9 | F10: =F7+F8+F9 | G10: =G7+G8+G9 | H10: =H7+H8+H9 | I10: =I7+I8+I9 | ... AE10: =AE7+AE8+AE9
A12: INCOME & EXPENSES
A13: Social Security | B13: =IF(B4,SSAnnual,SurvivorSS*12) | C13: =IF(C4,B13*(1+SSCOLA),SurvivorSS*12*(1+SSCOLA)^1) | D13: =IF(D4,C13*(1+SSCOLA),SurvivorSS*12*(1+SSCOLA)^2) | E13: =IF(E4,D13*(1+SSCOLA),SurvivorSS*12*(1+SSCOLA)^3) | F13: =IF(F4,E13*(1+SSCOLA),SurvivorSS*12*(1+SSCOLA)^4) | G13: =IF(G4,F13*(1+SSCOLA),SurvivorSS*12*(1+SSCOLA)^5) | H13: =IF(H4,G13*(1+SSCOLA),SurvivorSS*12*(1+SSCOLA)^6) | I13: =IF(I4,H13*(1+SSCOLA),SurvivorSS*12*(1+SSCOLA)^7) | J13: =IF(J4,I13*(1+SSCOLA),SurvivorSS*12*(1+SSCOLA)^8) | K13: =IF(K4,J13*(1+SSCOLA),SurvivorSS*12*(1+SSCOLA)^9) | L13: =IF(L4,K13*(1+SSCOLA),SurvivorSS*12*(1+SSCOLA)^10) | M13: =IF(M4,L13*(1+SSCOLA),SurvivorSS*12*(1+SSCOLA)^11) | N13: =IF(N4,M13*(1+SSCOLA),SurvivorSS*12*(1+SSCOLA)^12) | O13: =IF(O4,N13*(1+SSCOLA),SurvivorSS*12*(1+SSCOLA)^13) | P13: =IF(P4,O13*(1+SSCOLA),SurvivorSS*12*(1+SSCOLA)^14) | Q13: =IF(Q4,P13*(1+SSCOLA),SurvivorSS*12*(1+SSCOLA)^15) | R13: =IF(R4,Q13*(1+SSCOLA),SurvivorSS*12*(1+SSCOLA)^16) | S13: =IF(S4,R13*(1+SSCOLA),SurvivorSS*12*(1+SSCOLA)^17) | T13: =IF(T4,S13*(1+SSCOLA),SurvivorSS*12*(1+SSCOLA)^18) | U13: =IF(U4,T13*(1+SSCOLA),SurvivorSS*12*(1+SSCOLA)^19) | V13: =IF(V4,U13*(1+SSCOLA),SurvivorSS*12*(1+SSCOLA)^20) | W13: =IF(W4,V13*(1+SSCOLA),SurvivorSS*12*(1+SSCOLA)^21) | X13: =IF(X4,W13*(1+SSCOLA),SurvivorSS*12*(1+SSCOLA)^22) | Y13: =IF(Y4,X13*(1+SSCOLA),SurvivorSS*12*(1+SSCOLA)^23) | Z13: =IF(Z4,Y13*(1+SSCOLA),SurvivorSS*12*(1+SSCOLA)^24) | AA13: =IF(AA4,Z13*(1+SSCOLA),SurvivorSS*12*(1+SSCOLA)^25) | AB13: =IF(AB4,AA13*(1+SSCOLA),SurvivorSS*12*(1+SSCOLA)^26) | AC13: =IF(AC4,AB13*(1+SSCOLA),SurvivorSS*12*(1+SSCOLA)^27) | AD13: =IF(AD4,AC13*(1+SSCOLA),SurvivorSS*12*(1+SSCOLA)^28) | AE13: =IF(AE4,AD13*(1+SSCOLA),SurvivorSS*12*(1+SSCOLA)^29)
A14: Other Income | B14: =IFERROR(VLOOKUP(B1,OtherIncomeTable,2,FALSE),0) | C14: =IFERROR(VLOOKUP(C1,OtherIncomeTable,2,FALSE),0) | D14: =IFERROR(VLOOKUP(D1,OtherIncomeTable,2,FALSE),0) | E14: =IFERROR(VLOOKUP(E1,OtherIncomeTable,2,FALSE),0) | F14: =IFERROR(VLOOKUP(F1,OtherIncomeTable,2,FALSE),0) | G14: =IFERROR(VLOOKUP(G1,OtherIncomeTable,2,FALSE),0) | H14: =IFERROR(VLOOKUP(H1,OtherIncomeTable,2,FALSE),0) | I14: =IFERROR(VLOOKUP(I1,OtherIncomeTable,2,FALSE),0) | ... AE14: =IFERROR(VLOOKUP(AE1,OtherIncomeTable,2,FALSE),0)
A15: Base Expenses | B15: =StartExpenses | C15: =B15*(1+ExpenseInflation) | D15: =C15*(1+ExpenseInflation) | E15: =D15*(1+ExpenseInflation) | F15: =E15*(1+ExpenseInflation) | G15: =F15*(1+ExpenseInflation) | H15: =G15*(1+ExpenseInflation) | I15: =H15*(1+ExpenseInflation) | J15: =I15*(1+ExpenseInflation) | ... AE15: =AD15*(1+ExpenseInflation)
A16: RMD Required | B16: =IF(IF(B4,B2,B3)>=73,IFERROR(B8/VLOOKUP(IF(B4,B2,B3),RMDTable,2,TRUE),B8/2),0) | C16: =IF(IF(C4,C2,C3)>=73,IFERROR(C8/VLOOKUP(IF(C4,C2,C3),RMDTable,2,TRUE),C8/2),0) | D16: =IF(IF(D4,D2,D3)>=73,IFERROR(D8/VLOOKUP(IF(D4,D2,D3),RMDTable,2,TRUE),D8/2),0) | E16: =IF(IF(E4,E2,E3)>=73,IFERROR(E8/VLOOKUP(IF(E4,E2,E3),RMDTable,2,TRUE),E8/2),0) | F16: =IF(IF(F4,F2,F3)>=73,IFERROR(F8/VLOOKUP(IF(F4,F2,F3),RMDTable,2,TRUE),F8/2),0) | G16: =IF(IF(G4,G2,G3)>=73,IFERROR(G8/VLOOKUP(IF(G4,G2,G3),RMDTable,2,TRUE),G8/2),0) | H16: =IF(IF(H4,H2,H3)>=73,IFERROR(H8/VLOOKUP(IF(H4,H2,H3),RMDTable,2,TRUE),H8/2),0) | I16: =IF(IF(I4,I2,I3)>=73,IFERROR(I8/VLOOKUP(IF(I4,I2,I3),RMDTable,2,TRUE),I8/2),0) | ... AE16: =IF(IF(AE4,AE2,AE3)>=73,IFERROR(AE8/VLOOKUP(IF(AE4,AE2,AE3),RMDTable,2,TRUE),AE8/2),0)
A17: Roth Conversion | B17: =IFERROR(VLOOKUP(B1,RothConvTable,2,FALSE),0) | C17: =IFERROR(VLOOKUP(C1,RothConvTable,2,FALSE),0) | D17: =IFERROR(VLOOKUP(D1,RothConvTable,2,FALSE),0) | E17: =IFERROR(VLOOKUP(E1,RothConvTable,2,FALSE),0) | F17: =IFERROR(VLOOKUP(F1,RothConvTable,2,FALSE),0) | G17: =IFERROR(VLOOKUP(G1,RothConvTable,2,FALSE),0) | H17: =IFERROR(VLOOKUP(H1,RothConvTable,2,FALSE),0) | I17: =IFERROR(VLOOKUP(I1,RothConvTable,2,FALSE),0) | ... AE17: =IFERROR(VLOOKUP(AE1,RothConvTable,2,FALSE),0)
A19: INVESTMENT RETURNS
A20: Return After-Tax | B20: =IF(UseBlendedReturns="Yes",B7*'Risk Allocation'!B26,B7*ReturnAfterTax) | C20: =IF(UseBlendedReturns="Yes",C7*'Risk Allocation'!C26,C7*ReturnAfterTax) | D20: =IF(UseBlendedReturns="Yes",D7*'Risk Allocation'!D26,D7*ReturnAfterTax) | E20: =IF(UseBlendedReturns="Yes",E7*'Risk Allocation'!E26,E7*ReturnAfterTax) | F20: =IF(UseBlendedReturns="Yes",F7*'Risk Allocation'!F26,F7*ReturnAfterTax) | G20: =IF(UseBlendedReturns="Yes",G7*'Risk Allocation'!G26,G7*ReturnAfterTax) | H20: =IF(UseBlendedReturns="Yes",H7*'Risk Allocation'!H26,H7*ReturnAfterTax) | I20: =IF(UseBlendedReturns="Yes",I7*'Risk Allocation'!I26,I7*ReturnAfterTax) | ... AE20: =IF(UseBlendedReturns="Yes",AE7*'Risk Allocation'!AE26,AE7*ReturnAfterTax)
A21: Return IRA | B21: =IF(UseBlendedReturns="Yes",MAX(0,(B8-B17))*'Risk Allocation'!B27,MAX(0,(B8-B17))*ReturnIRA) | C21: =IF(UseBlendedReturns="Yes",MAX(0,(C8-C17))*'Risk Allocation'!C27,MAX(0,(C8-C17))*ReturnIRA) | D21: =IF(UseBlendedReturns="Yes",MAX(0,(D8-D17))*'Risk Allocation'!D27,MAX(0,(D8-D17))*ReturnIRA) | E21: =IF(UseBlendedReturns="Yes",MAX(0,(E8-E17))*'Risk Allocation'!E27,MAX(0,(E8-E17))*ReturnIRA) | F21: =IF(UseBlendedReturns="Yes",MAX(0,(F8-F17))*'Risk Allocation'!F27,MAX(0,(F8-F17))*ReturnIRA) | G21: =IF(UseBlendedReturns="Yes",MAX(0,(G8-G17))*'Risk Allocation'!G27,MAX(0,(G8-G17))*ReturnIRA) | H21: =IF(UseBlendedReturns="Yes",MAX(0,(H8-H17))*'Risk Allocation'!H27,MAX(0,(H8-H17))*ReturnIRA) | I21: =IF(UseBlendedReturns="Yes",MAX(0,(I8-I17))*'Risk Allocation'!I27,MAX(0,(I8-I17))*ReturnIRA) | ... AE21: =IF(UseBlendedReturns="Yes",MAX(0,(AE8-AE17))*'Risk Allocation'!AE27,MAX(0,(AE8-AE17))*ReturnIRA)
A22: Return Roth | B22: =IF(UseBlendedReturns="Yes",(B9+B17)*'Risk Allocation'!B28,(B9+B17)*ReturnRoth) | C22: =IF(UseBlendedReturns="Yes",(C9+C17)*'Risk Allocation'!C28,(C9+C17)*ReturnRoth) | D22: =IF(UseBlendedReturns="Yes",(D9+D17)*'Risk Allocation'!D28,(D9+D17)*ReturnRoth) | E22: =IF(UseBlendedReturns="Yes",(E9+E17)*'Risk Allocation'!E28,(E9+E17)*ReturnRoth) | F22: =IF(UseBlendedReturns="Yes",(F9+F17)*'Risk Allocation'!F28,(F9+F17)*ReturnRoth) | G22: =IF(UseBlendedReturns="Yes",(G9+G17)*'Risk Allocation'!G28,(G9+G17)*ReturnRoth) | H22: =IF(UseBlendedReturns="Yes",(H9+H17)*'Risk Allocation'!H28,(H9+H17)*ReturnRoth) | I22: =IF(UseBlendedReturns="Yes",(I9+I17)*'Risk Allocation'!I28,(I9+I17)*ReturnRoth) | ... AE22: =IF(UseBlendedReturns="Yes",(AE9+AE17)*'Risk Allocation'!AE28,(AE9+AE17)*ReturnRoth)
A24: IRMAA & TAXES
A25: Prior Yr MAGI (est) | B25: =MAGI2024 | C25: =MAGI2025 | D25: =B14+B16+B17+B33+0.85*B13+B32*CapGainsPct | E25: =C14+C16+C17+C33+0.85*C13+C32*CapGainsPct | F25: =D14+D16+D17+D33+0.85*D13+D32*CapGainsPct | G25: =E14+E16+E17+E33+0.85*E13+E32*CapGainsPct | H25: =F14+F16+F17+F33+0.85*F13+F32*CapGainsPct | I25: =G14+G16+G17+G33+0.85*G13+G32*CapGainsPct | J25: =H14+H16+H17+H33+0.85*H13+H32*CapGainsPct | K25: =I14+I16+I17+I33+0.85*I13+I32*CapGainsPct | ... AE25: =AC14+AC16+AC17+AC33+0.85*AC13+AC32*CapGainsPct
A26: IRMAA | B26: =IF(B4,IF(B25<=IRMAA_MFJ_Thresh1*(1+TaxBracketInflation)^0,IRMAA_MFJ_Cost1*(1+SSCOLA)^0,IF(B25<=IRMAA_MFJ_Thresh2*(1+TaxBracketInflation)^0,IRMAA_MFJ_Cost2*(1+SSCOLA)^0,IF(B25<=IRMAA_MFJ_Thresh3*(1+TaxBracketInflation)^0,IRMAA_MFJ_Cost3*(1+SSCOLA)^0,IF(B25<=IRMAA_MFJ_Thresh4*(1+TaxBracketInflation)^0,IRMAA_MFJ_Cost4*(1+SSCOLA)^0,IF(B25<=IRMAA_MFJ_Thresh5*(1+TaxBracketInflation)^0,IRMAA_MFJ_Cost5*(1+SSCOLA)^0,IRMAA_MFJ_Cost6*(1+SSCOLA)^0))))),IF(B25<=IRMAA_Single_Thresh1*(1+TaxBracketInflation)^0,IRMAA_Single_Cost1*(1+SSCOLA)^0,IF(B25<=IRMAA_Single_Thresh2*(1+TaxBracketInflation)^0,IRMAA_Single_Cost2*(1+SSCOLA)^0,IF(B25<=IRMAA_Single_Thresh3*(1+TaxBracketInflation)^0,IRMAA_Single_Cost3*(1+SSCOLA)^0,IF(B25<=IRMAA_Single_Thresh4*(1+TaxBracketInflation)^0,IRMAA_Single_Cost4*(1+SSCOLA)^0,IF(B25<=IRMAA_Single_Thresh5*(1+TaxBracketInflation)^0,IRMAA_Single_Cost5*(1+SSCOLA)^0,IRMAA_Single_Cost6*(1+SSCOLA)^0)))))) | C26: =IF(C4,IF(C25<=IRMAA_MFJ_Thresh1*(1+TaxBracketInflation)^1,IRMAA_MFJ_Cost1*(1+SSCOLA)^1,IF(C25<=IRMAA_MFJ_Thresh2*(1+TaxBracketInflation)^1,IRMAA_MFJ_Cost2*(1+SSCOLA)^1,IF(C25<=IRMAA_MFJ_Thresh3*(1+TaxBracketInflation)^1,IRMAA_MFJ_Cost3*(1+SSCOLA)^1,IF(C25<=IRMAA_MFJ_Thresh4*(1+TaxBracketInflation)^1,IRMAA_MFJ_Cost4*(1+SSCOLA)^1,IF(C25<=IRMAA_MFJ_Thresh5*(1+TaxBracketInflation)^1,IRMAA_MFJ_Cost5*(1+SSCOLA)^1,IRMAA_MFJ_Cost6*(1+SSCOLA)^1))))),IF(C25<=IRMAA_Single_Thresh1*(1+TaxBracketInflation)^1,IRMAA_Single_Cost1*(1+SSCOLA)^1,IF(C25<=IRMAA_Single_Thresh2*(1+TaxBracketInflation)^1,IRMAA_Single_Cost2*(1+SSCOLA)^1,IF(C25<=IRMAA_Single_Thresh3*(1+TaxBracketInflation)^1,IRMAA_Single_Cost3*(1+SSCOLA)^1,IF(C25<=IRMAA_Single_Thresh4*(1+TaxBracketInflation)^1,IRMAA_Single_Cost4*(1+SSCOLA)^1,IF(C25<=IRMAA_Single_Thresh5*(1+TaxBracketInflation)^1,IRMAA_Single_Cost5*(1+SSCOLA)^1,IRMAA_Single_Cost6*(1+SSCOLA)^1)))))) | D26: =IF(D4,IF(D25<=IRMAA_MFJ_Thresh1*(1+TaxBracketInflation)^2,IRMAA_MFJ_Cost1*(1+SSCOLA)^2,IF(D25<=IRMAA_MFJ_Thresh2*(1+TaxBracketInflation)^2,IRMAA_MFJ_Cost2*(1+SSCOLA)^2,IF(D25<=IRMAA_MFJ_Thresh3*(1+TaxBracketInflation)^2,IRMAA_MFJ_Cost3*(1+SSCOLA)^2,IF(D25<=IRMAA_MFJ_Thresh4*(1+TaxBracketInflation)^2,IRMAA_MFJ_Cost4*(1+SSCOLA)^2,IF(D25<=IRMAA_MFJ_Thresh5*(1+TaxBracketInflation)^2,IRMAA_MFJ_Cost5*(1+SSCOLA)^2,IRMAA_MFJ_Cost6*(1+SSCOLA)^2))))),IF(D25<=IRMAA_Single_Thresh1*(1+TaxBracketInflation)^2,IRMAA_Single_Cost1*(1+SSCOLA)^2,IF(D25<=IRMAA_Single_Thresh2*(1+TaxBracketInflation)^2,IRMAA_Single_Cost2*(1+SSCOLA)^2,IF(D25<=IRMAA_Single_Thresh3*(1+TaxBracketInflation)^2,IRMAA_Single_Cost3*(1+SSCOLA)^2,IF(D25<=IRMAA_Single_Thresh4*(1+TaxBracketInflation)^2,IRMAA_Single_Cost4*(1+SSCOLA)^2,IF(D25<=IRMAA_Single_Thresh5*(1+TaxBracketInflation)^2,IRMAA_Single_Cost5*(1+SSCOLA)^2,IRMAA_Single_Cost6*(1+SSCOLA)^2)))))) | E26: =IF(E4,IF(E25<=IRMAA_MFJ_Thresh1*(1+TaxBracketInflation)^3,IRMAA_MFJ_Cost1*(1+SSCOLA)^3,IF(E25<=IRMAA_MFJ_Thresh2*(1+TaxBracketInflation)^3,IRMAA_MFJ_Cost2*(1+SSCOLA)^3,IF(E25<=IRMAA_MFJ_Thresh3*(1+TaxBracketInflation)^3,IRMAA_MFJ_Cost3*(1+SSCOLA)^3,IF(E25<=IRMAA_MFJ_Thresh4*(1+TaxBracketInflation)^3,IRMAA_MFJ_Cost4*(1+SSCOLA)^3,IF(E25<=IRMAA_MFJ_Thresh5*(1+TaxBracketInflation)^3,IRMAA_MFJ_Cost5*(1+SSCOLA)^3,IRMAA_MFJ_Cost6*(1+SSCOLA)^3))))),IF(E25<=IRMAA_Single_Thresh1*(1+TaxBracketInflation)^3,IRMAA_Single_Cost1*(1+SSCOLA)^3,IF(E25<=IRMAA_Single_Thresh2*(1+TaxBracketInflation)^3,IRMAA_Single_Cost2*(1+SSCOLA)^3,IF(E25<=IRMAA_Single_Thresh3*(1+TaxBracketInflation)^3,IRMAA_Single_Cost3*(1+SSCOLA)^3,IF(E25<=IRMAA_Single_Thresh4*(1+TaxBracketInflation)^3,IRMAA_Single_Cost4*(1+SSCOLA)^3,IF(E25<=IRMAA_Single_Thresh5*(1+TaxBracketInflation)^3,IRMAA_Single_Cost5*(1+SSCOLA)^3,IRMAA_Single_Cost6*(1+SSCOLA)^3)))))) | F26: =IF(F4,IF(F25<=IRMAA_MFJ_Thresh1*(1+TaxBracketInflation)^4,IRMAA_MFJ_Cost1*(1+SSCOLA)^4,IF(F25<=IRMAA_MFJ_Thresh2*(1+TaxBracketInflation)^4,IRMAA_MFJ_Cost2*(1+SSCOLA)^4,IF(F25<=IRMAA_MFJ_Thresh3*(1+TaxBracketInflation)^4,IRMAA_MFJ_Cost3*(1+SSCOLA)^4,IF(F25<=IRMAA_MFJ_Thresh4*(1+TaxBracketInflation)^4,IRMAA_MFJ_Cost4*(1+SSCOLA)^4,IF(F25<=IRMAA_MFJ_Thresh5*(1+TaxBracketInflation)^4,IRMAA_MFJ_Cost5*(1+SSCOLA)^4,IRMAA_MFJ_Cost6*(1+SSCOLA)^4))))),IF(F25<=IRMAA_Single_Thresh1*(1+TaxBracketInflation)^4,IRMAA_Single_Cost1*(1+SSCOLA)^4,IF(F25<=IRMAA_Single_Thresh2*(1+TaxBracketInflation)^4,IRMAA_Single_Cost2*(1+SSCOLA)^4,IF(F25<=IRMAA_Single_Thresh3*(1+TaxBracketInflation)^4,IRMAA_Single_Cost3*(1+SSCOLA)^4,IF(F25<=IRMAA_Single_Thresh4*(1+TaxBracketInflation)^4,IRMAA_Single_Cost4*(1+SSCOLA)^4,IF(F25<=IRMAA_Single_Thresh5*(1+TaxBracketInflation)^4,IRMAA_Single_Cost5*(1+SSCOLA)^4,IRMAA_Single_Cost6*(1+SSCOLA)^4)))))) | G26: =IF(G4,IF(G25<=IRMAA_MFJ_Thresh1*(1+TaxBracketInflation)^5,IRMAA_MFJ_Cost1*(1+SSCOLA)^5,IF(G25<=IRMAA_MFJ_Thresh2*(1+TaxBracketInflation)^5,IRMAA_MFJ_Cost2*(1+SSCOLA)^5,IF(G25<=IRMAA_MFJ_Thresh3*(1+TaxBracketInflation)^5,IRMAA_MFJ_Cost3*(1+SSCOLA)^5,IF(G25<=IRMAA_MFJ_Thresh4*(1+TaxBracketInflation)^5,IRMAA_MFJ_Cost4*(1+SSCOLA)^5,IF(G25<=IRMAA_MFJ_Thresh5*(1+TaxBracketInflation)^5,IRMAA_MFJ_Cost5*(1+SSCOLA)^5,IRMAA_MFJ_Cost6*(1+SSCOLA)^5))))),IF(G25<=IRMAA_Single_Thresh1*(1+TaxBracketInflation)^5,IRMAA_Single_Cost1*(1+SSCOLA)^5,IF(G25<=IRMAA_Single_Thresh2*(1+TaxBracketInflation)^5,IRMAA_Single_Cost2*(1+SSCOLA)^5,IF(G25<=IRMAA_Single_Thresh3*(1+TaxBracketInflation)^5,IRMAA_Single_Cost3*(1+SSCOLA)^5,IF(G25<=IRMAA_Single_Thresh4*(1+TaxBracketInflation)^5,IRMAA_Single_Cost4*(1+SSCOLA)^5,IF(G25<=IRMAA_Single_Thresh5*(1+TaxBracketInflation)^5,IRMAA_Single_Cost5*(1+SSCOLA)^5,IRMAA_Single_Cost6*(1+SSCOLA)^5)))))) | H26: =IF(H4,IF(H25<=IRMAA_MFJ_Thresh1*(1+TaxBracketInflation)^6,IRMAA_MFJ_Cost1*(1+SSCOLA)^6,IF(H25<=IRMAA_MFJ_Thresh2*(1+TaxBracketInflation)^6,IRMAA_MFJ_Cost2*(1+SSCOLA)^6,IF(H25<=IRMAA_MFJ_Thresh3*(1+TaxBracketInflation)^6,IRMAA_MFJ_Cost3*(1+SSCOLA)^6,IF(H25<=IRMAA_MFJ_Thresh4*(1+TaxBracketInflation)^6,IRMAA_MFJ_Cost4*(1+SSCOLA)^6,IF(H25<=IRMAA_MFJ_Thresh5*(1+TaxBracketInflation)^6,IRMAA_MFJ_Cost5*(1+SSCOLA)^6,IRMAA_MFJ_Cost6*(1+SSCOLA)^6))))),IF(H25<=IRMAA_Single_Thresh1*(1+TaxBracketInflation)^6,IRMAA_Single_Cost1*(1+SSCOLA)^6,IF(H25<=IRMAA_Single_Thresh2*(1+TaxBracketInflation)^6,IRMAA_Single_Cost2*(1+SSCOLA)^6,IF(H25<=IRMAA_Single_Thresh3*(1+TaxBracketInflation)^6,IRMAA_Single_Cost3*(1+SSCOLA)^6,IF(H25<=IRMAA_Single_Thresh4*(1+TaxBracketInflation)^6,IRMAA_Single_Cost4*(1+SSCOLA)^6,IF(H25<=IRMAA_Single_Thresh5*(1+TaxBracketInflation)^6,IRMAA_Single_Cost5*(1+SSCOLA)^6,IRMAA_Single_Cost6*(1+SSCOLA)^6)))))) | I26: =IF(I4,IF(I25<=IRMAA_MFJ_Thresh1*(1+TaxBracketInflation)^7,IRMAA_MFJ_Cost1*(1+SSCOLA)^7,IF(I25<=IRMAA_MFJ_Thresh2*(1+TaxBracketInflation)^7,IRMAA_MFJ_Cost2*(1+SSCOLA)^7,IF(I25<=IRMAA_MFJ_Thresh3*(1+TaxBracketInflation)^7,IRMAA_MFJ_Cost3*(1+SSCOLA)^7,IF(I25<=IRMAA_MFJ_Thresh4*(1+TaxBracketInflation)^7,IRMAA_MFJ_Cost4*(1+SSCOLA)^7,IF(I25<=IRMAA_MFJ_Thresh5*(1+TaxBracketInflation)^7,IRMAA_MFJ_Cost5*(1+SSCOLA)^7,IRMAA_MFJ_Cost6*(1+SSCOLA)^7))))),IF(I25<=IRMAA_Single_Thresh1*(1+TaxBracketInflation)^7,IRMAA_Single_Cost1*(1+SSCOLA)^7,IF(I25<=IRMAA_Single_Thresh2*(1+TaxBracketInflation)^7,IRMAA_Single_Cost2*(1+SSCOLA)^7,IF(I25<=IRMAA_Single_Thresh3*(1+TaxBracketInflation)^7,IRMAA_Single_Cost3*(1+SSCOLA)^7,IF(I25<=IRMAA_Single_Thresh4*(1+TaxBracketInflation)^7,IRMAA_Single_Cost4*(1+SSCOLA)^7,IF(I25<=IRMAA_Single_Thresh5*(1+TaxBracketInflation)^7,IRMAA_Single_Cost5*(1+SSCOLA)^7,IRMAA_Single_Cost6*(1+SSCOLA)^7)))))) | J26: =IF(J4,IF(J25<=IRMAA_MFJ_Thresh1*(1+TaxBracketInflation)^8,IRMAA_MFJ_Cost1*(1+SSCOLA)^8,IF(J25<=IRMAA_MFJ_Thresh2*(1+TaxBracketInflation)^8,IRMAA_MFJ_Cost2*(1+SSCOLA)^8,IF(J25<=IRMAA_MFJ_Thresh3*(1+TaxBracketInflation)^8,IRMAA_MFJ_Cost3*(1+SSCOLA)^8,IF(J25<=IRMAA_MFJ_Thresh4*(1+TaxBracketInflation)^8,IRMAA_MFJ_Cost4*(1+SSCOLA)^8,IF(J25<=IRMAA_MFJ_Thresh5*(1+TaxBracketInflation)^8,IRMAA_MFJ_Cost5*(1+SSCOLA)^8,IRMAA_MFJ_Cost6*(1+SSCOLA)^8))))),IF(J25<=IRMAA_Single_Thresh1*(1+TaxBracketInflation)^8,IRMAA_Single_Cost1*(1+SSCOLA)^8,IF(J25<=IRMAA_Single_Thresh2*(1+TaxBracketInflation)^8,IRMAA_Single_Cost2*(1+SSCOLA)^8,IF(J25<=IRMAA_Single_Thresh3*(1+TaxBracketInflation)^8,IRMAA_Single_Cost3*(1+SSCOLA)^8,IF(J25<=IRMAA_Single_Thresh4*(1+TaxBracketInflation)^8,IRMAA_Single_Cost4*(1+SSCOLA)^8,IF(J25<=IRMAA_Single_Thresh5*(1+TaxBracketInflation)^8,IRMAA_Single_Cost5*(1+SSCOLA)^8,IRMAA_Single_Cost6*(1+SSCOLA)^8)))))) | K26: =IF(K4,IF(K25<=IRMAA_MFJ_Thresh1*(1+TaxBracketInflation)^9,IRMAA_MFJ_Cost1*(1+SSCOLA)^9,IF(K25<=IRMAA_MFJ_Thresh2*(1+TaxBracketInflation)^9,IRMAA_MFJ_Cost2*(1+SSCOLA)^9,IF(K25<=IRMAA_MFJ_Thresh3*(1+TaxBracketInflation)^9,IRMAA_MFJ_Cost3*(1+SSCOLA)^9,IF(K25<=IRMAA_MFJ_Thresh4*(1+TaxBracketInflation)^9,IRMAA_MFJ_Cost4*(1+SSCOLA)^9,IF(K25<=IRMAA_MFJ_Thresh5*(1+TaxBracketInflation)^9,IRMAA_MFJ_Cost5*(1+SSCOLA)^9,IRMAA_MFJ_Cost6*(1+SSCOLA)^9))))),IF(K25<=IRMAA_Single_Thresh1*(1+TaxBracketInflation)^9,IRMAA_Single_Cost1*(1+SSCOLA)^9,IF(K25<=IRMAA_Single_Thresh2*(1+TaxBracketInflation)^9,IRMAA_Single_Cost2*(1+SSCOLA)^9,IF(K25<=IRMAA_Single_Thresh3*(1+TaxBracketInflation)^9,IRMAA_Single_Cost3*(1+SSCOLA)^9,IF(K25<=IRMAA_Single_Thresh4*(1+TaxBracketInflation)^9,IRMAA_Single_Cost4*(1+SSCOLA)^9,IF(K25<=IRMAA_Single_Thresh5*(1+TaxBracketInflation)^9,IRMAA_Single_Cost5*(1+SSCOLA)^9,IRMAA_Single_Cost6*(1+SSCOLA)^9)))))) | L26: =IF(L4,IF(L25<=IRMAA_MFJ_Thresh1*(1+TaxBracketInflation)^10,IRMAA_MFJ_Cost1*(1+SSCOLA)^10,IF(L25<=IRMAA_MFJ_Thresh2*(1+TaxBracketInflation)^10,IRMAA_MFJ_Cost2*(1+SSCOLA)^10,IF(L25<=IRMAA_MFJ_Thresh3*(1+TaxBracketInflation)^10,IRMAA_MFJ_Cost3*(1+SSCOLA)^10,IF(L25<=IRMAA_MFJ_Thresh4*(1+TaxBracketInflation)^10,IRMAA_MFJ_Cost4*(1+SSCOLA)^10,IF(L25<=IRMAA_MFJ_Thresh5*(1+TaxBracketInflation)^10,IRMAA_MFJ_Cost5*(1+SSCOLA)^10,IRMAA_MFJ_Cost6*(1+SSCOLA)^10))))),IF(L25<=IRMAA_Single_Thresh1*(1+TaxBracketInflation)^10,IRMAA_Single_Cost1*(1+SSCOLA)^10,IF(L25<=IRMAA_Single_Thresh2*(1+TaxBracketInflation)^10,IRMAA_Single_Cost2*(1+SSCOLA)^10,IF(L25<=IRMAA_Single_Thresh3*(1+TaxBracketInflation)^10,IRMAA_Single_Cost3*(1+SSCOLA)^10,IF(L25<=IRMAA_Single_Thresh4*(1+TaxBracketInflation)^10,IRMAA_Single_Cost4*(1+SSCOLA)^10,IF(L25<=IRMAA_Single_Thresh5*(1+TaxBracketInflation)^10,IRMAA_Single_Cost5*(1+SSCOLA)^10,IRMAA_Single_Cost6*(1+SSCOLA)^10)))))) | M26: =IF(M4,IF(M25<=IRMAA_MFJ_Thresh1*(1+TaxBracketInflation)^11,IRMAA_MFJ_Cost1*(1+SSCOLA)^11,IF(M25<=IRMAA_MFJ_Thresh2*(1+TaxBracketInflation)^11,IRMAA_MFJ_Cost2*(1+SSCOLA)^11,IF(M25<=IRMAA_MFJ_Thresh3*(1+TaxBracketInflation)^11,IRMAA_MFJ_Cost3*(1+SSCOLA)^11,IF(M25<=IRMAA_MFJ_Thresh4*(1+TaxBracketInflation)^11,IRMAA_MFJ_Cost4*(1+SSCOLA)^11,IF(M25<=IRMAA_MFJ_Thresh5*(1+TaxBracketInflation)^11,IRMAA_MFJ_Cost5*(1+SSCOLA)^11,IRMAA_MFJ_Cost6*(1+SSCOLA)^11))))),IF(M25<=IRMAA_Single_Thresh1*(1+TaxBracketInflation)^11,IRMAA_Single_Cost1*(1+SSCOLA)^11,IF(M25<=IRMAA_Single_Thresh2*(1+TaxBracketInflation)^11,IRMAA_Single_Cost2*(1+SSCOLA)^11,IF(M25<=IRMAA_Single_Thresh3*(1+TaxBracketInflation)^11,IRMAA_Single_Cost3*(1+SSCOLA)^11,IF(M25<=IRMAA_Single_Thresh4*(1+TaxBracketInflation)^11,IRMAA_Single_Cost4*(1+SSCOLA)^11,IF(M25<=IRMAA_Single_Thresh5*(1+TaxBracketInflation)^11,IRMAA_Single_Cost5*(1+SSCOLA)^11,IRMAA_Single_Cost6*(1+SSCOLA)^11)))))) | N26: =IF(N4,IF(N25<=IRMAA_MFJ_Thresh1*(1+TaxBracketInflation)^12,IRMAA_MFJ_Cost1*(1+SSCOLA)^12,IF(N25<=IRMAA_MFJ_Thresh2*(1+TaxBracketInflation)^12,IRMAA_MFJ_Cost2*(1+SSCOLA)^12,IF(N25<=IRMAA_MFJ_Thresh3*(1+TaxBracketInflation)^12,IRMAA_MFJ_Cost3*(1+SSCOLA)^12,IF(N25<=IRMAA_MFJ_Thresh4*(1+TaxBracketInflation)^12,IRMAA_MFJ_Cost4*(1+SSCOLA)^12,IF(N25<=IRMAA_MFJ_Thresh5*(1+TaxBracketInflation)^12,IRMAA_MFJ_Cost5*(1+SSCOLA)^12,IRMAA_MFJ_Cost6*(1+SSCOLA)^12))))),IF(N25<=IRMAA_Single_Thresh1*(1+TaxBracketInflation)^12,IRMAA_Single_Cost1*(1+SSCOLA)^12,IF(N25<=IRMAA_Single_Thresh2*(1+TaxBracketInflation)^12,IRMAA_Single_Cost2*(1+SSCOLA)^12,IF(N25<=IRMAA_Single_Thresh3*(1+TaxBracketInflation)^12,IRMAA_Single_Cost3*(1+SSCOLA)^12,IF(N25<=IRMAA_Single_Thresh4*(1+TaxBracketInflation)^12,IRMAA_Single_Cost4*(1+SSCOLA)^12,IF(N25<=IRMAA_Single_Thresh5*(1+TaxBracketInflation)^12,IRMAA_Single_Cost5*(1+SSCOLA)^12,IRMAA_Single_Cost6*(1+SSCOLA)^12)))))) | O26: =IF(O4,IF(O25<=IRMAA_MFJ_Thresh1*(1+TaxBracketInflation)^13,IRMAA_MFJ_Cost1*(1+SSCOLA)^13,IF(O25<=IRMAA_MFJ_Thresh2*(1+TaxBracketInflation)^13,IRMAA_MFJ_Cost2*(1+SSCOLA)^13,IF(O25<=IRMAA_MFJ_Thresh3*(1+TaxBracketInflation)^13,IRMAA_MFJ_Cost3*(1+SSCOLA)^13,IF(O25<=IRMAA_MFJ_Thresh4*(1+TaxBracketInflation)^13,IRMAA_MFJ_Cost4*(1+SSCOLA)^13,IF(O25<=IRMAA_MFJ_Thresh5*(1+TaxBracketInflation)^13,IRMAA_MFJ_Cost5*(1+SSCOLA)^13,IRMAA_MFJ_Cost6*(1+SSCOLA)^13))))),IF(O25<=IRMAA_Single_Thresh1*(1+TaxBracketInflation)^13,IRMAA_Single_Cost1*(1+SSCOLA)^13,IF(O25<=IRMAA_Single_Thresh2*(1+TaxBracketInflation)^13,IRMAA_Single_Cost2*(1+SSCOLA)^13,IF(O25<=IRMAA_Single_Thresh3*(1+TaxBracketInflation)^13,IRMAA_Single_Cost3*(1+SSCOLA)^13,IF(O25<=IRMAA_Single_Thresh4*(1+TaxBracketInflation)^13,IRMAA_Single_Cost4*(1+SSCOLA)^13,IF(O25<=IRMAA_Single_Thresh5*(1+TaxBracketInflation)^13,IRMAA_Single_Cost5*(1+SSCOLA)^13,IRMAA_Single_Cost6*(1+SSCOLA)^13)))))) | P26: =IF(P4,IF(P25<=IRMAA_MFJ_Thresh1*(1+TaxBracketInflation)^14,IRMAA_MFJ_Cost1*(1+SSCOLA)^14,IF(P25<=IRMAA_MFJ_Thresh2*(1+TaxBracketInflation)^14,IRMAA_MFJ_Cost2*(1+SSCOLA)^14,IF(P25<=IRMAA_MFJ_Thresh3*(1+TaxBracketInflation)^14,IRMAA_MFJ_Cost3*(1+SSCOLA)^14,IF(P25<=IRMAA_MFJ_Thresh4*(1+TaxBracketInflation)^14,IRMAA_MFJ_Cost4*(1+SSCOLA)^14,IF(P25<=IRMAA_MFJ_Thresh5*(1+TaxBracketInflation)^14,IRMAA_MFJ_Cost5*(1+SSCOLA)^14,IRMAA_MFJ_Cost6*(1+SSCOLA)^14))))),IF(P25<=IRMAA_Single_Thresh1*(1+TaxBracketInflation)^14,IRMAA_Single_Cost1*(1+SSCOLA)^14,IF(P25<=IRMAA_Single_Thresh2*(1+TaxBracketInflation)^14,IRMAA_Single_Cost2*(1+SSCOLA)^14,IF(P25<=IRMAA_Single_Thresh3*(1+TaxBracketInflation)^14,IRMAA_Single_Cost3*(1+SSCOLA)^14,IF(P25<=IRMAA_Single_Thresh4*(1+TaxBracketInflation)^14,IRMAA_Single_Cost4*(1+SSCOLA)^14,IF(P25<=IRMAA_Single_Thresh5*(1+TaxBracketInflation)^14,IRMAA_Single_Cost5*(1+SSCOLA)^14,IRMAA_Single_Cost6*(1+SSCOLA)^14)))))) | Q26: =IF(Q4,IF(Q25<=IRMAA_MFJ_Thresh1*(1+TaxBracketInflation)^15,IRMAA_MFJ_Cost1*(1+SSCOLA)^15,IF(Q25<=IRMAA_MFJ_Thresh2*(1+TaxBracketInflation)^15,IRMAA_MFJ_Cost2*(1+SSCOLA)^15,IF(Q25<=IRMAA_MFJ_Thresh3*(1+TaxBracketInflation)^15,IRMAA_MFJ_Cost3*(1+SSCOLA)^15,IF(Q25<=IRMAA_MFJ_Thresh4*(1+TaxBracketInflation)^15,IRMAA_MFJ_Cost4*(1+SSCOLA)^15,IF(Q25<=IRMAA_MFJ_Thresh5*(1+TaxBracketInflation)^15,IRMAA_MFJ_Cost5*(1+SSCOLA)^15,IRMAA_MFJ_Cost6*(1+SSCOLA)^15))))),IF(Q25<=IRMAA_Single_Thresh1*(1+TaxBracketInflation)^15,IRMAA_Single_Cost1*(1+SSCOLA)^15,IF(Q25<=IRMAA_Single_Thresh2*(1+TaxBracketInflation)^15,IRMAA_Single_Cost2*(1+SSCOLA)^15,IF(Q25<=IRMAA_Single_Thresh3*(1+TaxBracketInflation)^15,IRMAA_Single_Cost3*(1+SSCOLA)^15,IF(Q25<=IRMAA_Single_Thresh4*(1+TaxBracketInflation)^15,IRMAA_Single_Cost4*(1+SSCOLA)^15,IF(Q25<=IRMAA_Single_Thresh5*(1+TaxBracketInflation)^15,IRMAA_Single_Cost5*(1+SSCOLA)^15,IRMAA_Single_Cost6*(1+SSCOLA)^15)))))) | R26: =IF(R4,IF(R25<=IRMAA_MFJ_Thresh1*(1+TaxBracketInflation)^16,IRMAA_MFJ_Cost1*(1+SSCOLA)^16,IF(R25<=IRMAA_MFJ_Thresh2*(1+TaxBracketInflation)^16,IRMAA_MFJ_Cost2*(1+SSCOLA)^16,IF(R25<=IRMAA_MFJ_Thresh3*(1+TaxBracketInflation)^16,IRMAA_MFJ_Cost3*(1+SSCOLA)^16,IF(R25<=IRMAA_MFJ_Thresh4*(1+TaxBracketInflation)^16,IRMAA_MFJ_Cost4*(1+SSCOLA)^16,IF(R25<=IRMAA_MFJ_Thresh5*(1+TaxBracketInflation)^16,IRMAA_MFJ_Cost5*(1+SSCOLA)^16,IRMAA_MFJ_Cost6*(1+SSCOLA)^16))))),IF(R25<=IRMAA_Single_Thresh1*(1+TaxBracketInflation)^16,IRMAA_Single_Cost1*(1+SSCOLA)^16,IF(R25<=IRMAA_Single_Thresh2*(1+TaxBracketInflation)^16,IRMAA_Single_Cost2*(1+SSCOLA)^16,IF(R25<=IRMAA_Single_Thresh3*(1+TaxBracketInflation)^16,IRMAA_Single_Cost3*(1+SSCOLA)^16,IF(R25<=IRMAA_Single_Thresh4*(1+TaxBracketInflation)^16,IRMAA_Single_Cost4*(1+SSCOLA)^16,IF(R25<=IRMAA_Single_Thresh5*(1+TaxBracketInflation)^16,IRMAA_Single_Cost5*(1+SSCOLA)^16,IRMAA_Single_Cost6*(1+SSCOLA)^16)))))) | S26: =IF(S4,IF(S25<=IRMAA_MFJ_Thresh1*(1+TaxBracketInflation)^17,IRMAA_MFJ_Cost1*(1+SSCOLA)^17,IF(S25<=IRMAA_MFJ_Thresh2*(1+TaxBracketInflation)^17,IRMAA_MFJ_Cost2*(1+SSCOLA)^17,IF(S25<=IRMAA_MFJ_Thresh3*(1+TaxBracketInflation)^17,IRMAA_MFJ_Cost3*(1+SSCOLA)^17,IF(S25<=IRMAA_MFJ_Thresh4*(1+TaxBracketInflation)^17,IRMAA_MFJ_Cost4*(1+SSCOLA)^17,IF(S25<=IRMAA_MFJ_Thresh5*(1+TaxBracketInflation)^17,IRMAA_MFJ_Cost5*(1+SSCOLA)^17,IRMAA_MFJ_Cost6*(1+SSCOLA)^17))))),IF(S25<=IRMAA_Single_Thresh1*(1+TaxBracketInflation)^17,IRMAA_Single_Cost1*(1+SSCOLA)^17,IF(S25<=IRMAA_Single_Thresh2*(1+TaxBracketInflation)^17,IRMAA_Single_Cost2*(1+SSCOLA)^17,IF(S25<=IRMAA_Single_Thresh3*(1+TaxBracketInflation)^17,IRMAA_Single_Cost3*(1+SSCOLA)^17,IF(S25<=IRMAA_Single_Thresh4*(1+TaxBracketInflation)^17,IRMAA_Single_Cost4*(1+SSCOLA)^17,IF(S25<=IRMAA_Single_Thresh5*(1+TaxBracketInflation)^17,IRMAA_Single_Cost5*(1+SSCOLA)^17,IRMAA_Single_Cost6*(1+SSCOLA)^17)))))) | T26: =IF(T4,IF(T25<=IRMAA_MFJ_Thresh1*(1+TaxBracketInflation)^18,IRMAA_MFJ_Cost1*(1+SSCOLA)^18,IF(T25<=IRMAA_MFJ_Thresh2*(1+TaxBracketInflation)^18,IRMAA_MFJ_Cost2*(1+SSCOLA)^18,IF(T25<=IRMAA_MFJ_Thresh3*(1+TaxBracketInflation)^18,IRMAA_MFJ_Cost3*(1+SSCOLA)^18,IF(T25<=IRMAA_MFJ_Thresh4*(1+TaxBracketInflation)^18,IRMAA_MFJ_Cost4*(1+SSCOLA)^18,IF(T25<=IRMAA_MFJ_Thresh5*(1+TaxBracketInflation)^18,IRMAA_MFJ_Cost5*(1+SSCOLA)^18,IRMAA_MFJ_Cost6*(1+SSCOLA)^18))))),IF(T25<=IRMAA_Single_Thresh1*(1+TaxBracketInflation)^18,IRMAA_Single_Cost1*(1+SSCOLA)^18,IF(T25<=IRMAA_Single_Thresh2*(1+TaxBracketInflation)^18,IRMAA_Single_Cost2*(1+SSCOLA)^18,IF(T25<=IRMAA_Single_Thresh3*(1+TaxBracketInflation)^18,IRMAA_Single_Cost3*(1+SSCOLA)^18,IF(T25<=IRMAA_Single_Thresh4*(1+TaxBracketInflation)^18,IRMAA_Single_Cost4*(1+SSCOLA)^18,IF(T25<=IRMAA_Single_Thresh5*(1+TaxBracketInflation)^18,IRMAA_Single_Cost5*(1+SSCOLA)^18,IRMAA_Single_Cost6*(1+SSCOLA)^18)))))) | U26: =IF(U4,IF(U25<=IRMAA_MFJ_Thresh1*(1+TaxBracketInflation)^19,IRMAA_MFJ_Cost1*(1+SSCOLA)^19,IF(U25<=IRMAA_MFJ_Thresh2*(1+TaxBracketInflation)^19,IRMAA_MFJ_Cost2*(1+SSCOLA)^19,IF(U25<=IRMAA_MFJ_Thresh3*(1+TaxBracketInflation)^19,IRMAA_MFJ_Cost3*(1+SSCOLA)^19,IF(U25<=IRMAA_MFJ_Thresh4*(1+TaxBracketInflation)^19,IRMAA_MFJ_Cost4*(1+SSCOLA)^19,IF(U25<=IRMAA_MFJ_Thresh5*(1+TaxBracketInflation)^19,IRMAA_MFJ_Cost5*(1+SSCOLA)^19,IRMAA_MFJ_Cost6*(1+SSCOLA)^19))))),IF(U25<=IRMAA_Single_Thresh1*(1+TaxBracketInflation)^19,IRMAA_Single_Cost1*(1+SSCOLA)^19,IF(U25<=IRMAA_Single_Thresh2*(1+TaxBracketInflation)^19,IRMAA_Single_Cost2*(1+SSCOLA)^19,IF(U25<=IRMAA_Single_Thresh3*(1+TaxBracketInflation)^19,IRMAA_Single_Cost3*(1+SSCOLA)^19,IF(U25<=IRMAA_Single_Thresh4*(1+TaxBracketInflation)^19,IRMAA_Single_Cost4*(1+SSCOLA)^19,IF(U25<=IRMAA_Single_Thresh5*(1+TaxBracketInflation)^19,IRMAA_Single_Cost5*(1+SSCOLA)^19,IRMAA_Single_Cost6*(1+SSCOLA)^19)))))) | V26: =IF(V4,IF(V25<=IRMAA_MFJ_Thresh1*(1+TaxBracketInflation)^20,IRMAA_MFJ_Cost1*(1+SSCOLA)^20,IF(V25<=IRMAA_MFJ_Thresh2*(1+TaxBracketInflation)^20,IRMAA_MFJ_Cost2*(1+SSCOLA)^20,IF(V25<=IRMAA_MFJ_Thresh3*(1+TaxBracketInflation)^20,IRMAA_MFJ_Cost3*(1+SSCOLA)^20,IF(V25<=IRMAA_MFJ_Thresh4*(1+TaxBracketInflation)^20,IRMAA_MFJ_Cost4*(1+SSCOLA)^20,IF(V25<=IRMAA_MFJ_Thresh5*(1+TaxBracketInflation)^20,IRMAA_MFJ_Cost5*(1+SSCOLA)^20,IRMAA_MFJ_Cost6*(1+SSCOLA)^20))))),IF(V25<=IRMAA_Single_Thresh1*(1+TaxBracketInflation)^20,IRMAA_Single_Cost1*(1+SSCOLA)^20,IF(V25<=IRMAA_Single_Thresh2*(1+TaxBracketInflation)^20,IRMAA_Single_Cost2*(1+SSCOLA)^20,IF(V25<=IRMAA_Single_Thresh3*(1+TaxBracketInflation)^20,IRMAA_Single_Cost3*(1+SSCOLA)^20,IF(V25<=IRMAA_Single_Thresh4*(1+TaxBracketInflation)^20,IRMAA_Single_Cost4*(1+SSCOLA)^20,IF(V25<=IRMAA_Single_Thresh5*(1+TaxBracketInflation)^20,IRMAA_Single_Cost5*(1+SSCOLA)^20,IRMAA_Single_Cost6*(1+SSCOLA)^20)))))) | W26: =IF(W4,IF(W25<=IRMAA_MFJ_Thresh1*(1+TaxBracketInflation)^21,IRMAA_MFJ_Cost1*(1+SSCOLA)^21,IF(W25<=IRMAA_MFJ_Thresh2*(1+TaxBracketInflation)^21,IRMAA_MFJ_Cost2*(1+SSCOLA)^21,IF(W25<=IRMAA_MFJ_Thresh3*(1+TaxBracketInflation)^21,IRMAA_MFJ_Cost3*(1+SSCOLA)^21,IF(W25<=IRMAA_MFJ_Thresh4*(1+TaxBracketInflation)^21,IRMAA_MFJ_Cost4*(1+SSCOLA)^21,IF(W25<=IRMAA_MFJ_Thresh5*(1+TaxBracketInflation)^21,IRMAA_MFJ_Cost5*(1+SSCOLA)^21,IRMAA_MFJ_Cost6*(1+SSCOLA)^21))))),IF(W25<=IRMAA_Single_Thresh1*(1+TaxBracketInflation)^21,IRMAA_Single_Cost1*(1+SSCOLA)^21,IF(W25<=IRMAA_Single_Thresh2*(1+TaxBracketInflation)^21,IRMAA_Single_Cost2*(1+SSCOLA)^21,IF(W25<=IRMAA_Single_Thresh3*(1+TaxBracketInflation)^21,IRMAA_Single_Cost3*(1+SSCOLA)^21,IF(W25<=IRMAA_Single_Thresh4*(1+TaxBracketInflation)^21,IRMAA_Single_Cost4*(1+SSCOLA)^21,IF(W25<=IRMAA_Single_Thresh5*(1+TaxBracketInflation)^21,IRMAA_Single_Cost5*(1+SSCOLA)^21,IRMAA_Single_Cost6*(1+SSCOLA)^21)))))) | X26: =IF(X4,IF(X25<=IRMAA_MFJ_Thresh1*(1+TaxBracketInflation)^22,IRMAA_MFJ_Cost1*(1+SSCOLA)^22,IF(X25<=IRMAA_MFJ_Thresh2*(1+TaxBracketInflation)^22,IRMAA_MFJ_Cost2*(1+SSCOLA)^22,IF(X25<=IRMAA_MFJ_Thresh3*(1+TaxBracketInflation)^22,IRMAA_MFJ_Cost3*(1+SSCOLA)^22,IF(X25<=IRMAA_MFJ_Thresh4*(1+TaxBracketInflation)^22,IRMAA_MFJ_Cost4*(1+SSCOLA)^22,IF(X25<=IRMAA_MFJ_Thresh5*(1+TaxBracketInflation)^22,IRMAA_MFJ_Cost5*(1+SSCOLA)^22,IRMAA_MFJ_Cost6*(1+SSCOLA)^22))))),IF(X25<=IRMAA_Single_Thresh1*(1+TaxBracketInflation)^22,IRMAA_Single_Cost1*(1+SSCOLA)^22,IF(X25<=IRMAA_Single_Thresh2*(1+TaxBracketInflation)^22,IRMAA_Single_Cost2*(1+SSCOLA)^22,IF(X25<=IRMAA_Single_Thresh3*(1+TaxBracketInflation)^22,IRMAA_Single_Cost3*(1+SSCOLA)^22,IF(X25<=IRMAA_Single_Thresh4*(1+TaxBracketInflation)^22,IRMAA_Single_Cost4*(1+SSCOLA)^22,IF(X25<=IRMAA_Single_Thresh5*(1+TaxBracketInflation)^22,IRMAA_Single_Cost5*(1+SSCOLA)^22,IRMAA_Single_Cost6*(1+SSCOLA)^22)))))) | Y26: =IF(Y4,IF(Y25<=IRMAA_MFJ_Thresh1*(1+TaxBracketInflation)^23,IRMAA_MFJ_Cost1*(1+SSCOLA)^23,IF(Y25<=IRMAA_MFJ_Thresh2*(1+TaxBracketInflation)^23,IRMAA_MFJ_Cost2*(1+SSCOLA)^23,IF(Y25<=IRMAA_MFJ_Thresh3*(1+TaxBracketInflation)^23,IRMAA_MFJ_Cost3*(1+SSCOLA)^23,IF(Y25<=IRMAA_MFJ_Thresh4*(1+TaxBracketInflation)^23,IRMAA_MFJ_Cost4*(1+SSCOLA)^23,IF(Y25<=IRMAA_MFJ_Thresh5*(1+TaxBracketInflation)^23,IRMAA_MFJ_Cost5*(1+SSCOLA)^23,IRMAA_MFJ_Cost6*(1+SSCOLA)^23))))),IF(Y25<=IRMAA_Single_Thresh1*(1+TaxBracketInflation)^23,IRMAA_Single_Cost1*(1+SSCOLA)^23,IF(Y25<=IRMAA_Single_Thresh2*(1+TaxBracketInflation)^23,IRMAA_Single_Cost2*(1+SSCOLA)^23,IF(Y25<=IRMAA_Single_Thresh3*(1+TaxBracketInflation)^23,IRMAA_Single_Cost3*(1+SSCOLA)^23,IF(Y25<=IRMAA_Single_Thresh4*(1+TaxBracketInflation)^23,IRMAA_Single_Cost4*(1+SSCOLA)^23,IF(Y25<=IRMAA_Single_Thresh5*(1+TaxBracketInflation)^23,IRMAA_Single_Cost5*(1+SSCOLA)^23,IRMAA_Single_Cost6*(1+SSCOLA)^23)))))) | Z26: =IF(Z4,IF(Z25<=IRMAA_MFJ_Thresh1*(1+TaxBracketInflation)^24,IRMAA_MFJ_Cost1*(1+SSCOLA)^24,IF(Z25<=IRMAA_MFJ_Thresh2*(1+TaxBracketInflation)^24,IRMAA_MFJ_Cost2*(1+SSCOLA)^24,IF(Z25<=IRMAA_MFJ_Thresh3*(1+TaxBracketInflation)^24,IRMAA_MFJ_Cost3*(1+SSCOLA)^24,IF(Z25<=IRMAA_MFJ_Thresh4*(1+TaxBracketInflation)^24,IRMAA_MFJ_Cost4*(1+SSCOLA)^24,IF(Z25<=IRMAA_MFJ_Thresh5*(1+TaxBracketInflation)^24,IRMAA_MFJ_Cost5*(1+SSCOLA)^24,IRMAA_MFJ_Cost6*(1+SSCOLA)^24))))),IF(Z25<=IRMAA_Single_Thresh1*(1+TaxBracketInflation)^24,IRMAA_Single_Cost1*(1+SSCOLA)^24,IF(Z25<=IRMAA_Single_Thresh2*(1+TaxBracketInflation)^24,IRMAA_Single_Cost2*(1+SSCOLA)^24,IF(Z25<=IRMAA_Single_Thresh3*(1+TaxBracketInflation)^24,IRMAA_Single_Cost3*(1+SSCOLA)^24,IF(Z25<=IRMAA_Single_Thresh4*(1+TaxBracketInflation)^24,IRMAA_Single_Cost4*(1+SSCOLA)^24,IF(Z25<=IRMAA_Single_Thresh5*(1+TaxBracketInflation)^24,IRMAA_Single_Cost5*(1+SSCOLA)^24,IRMAA_Single_Cost6*(1+SSCOLA)^24)))))) | AA26: =IF(AA4,IF(AA25<=IRMAA_MFJ_Thresh1*(1+TaxBracketInflation)^25,IRMAA_MFJ_Cost1*(1+SSCOLA)^25,IF(AA25<=IRMAA_MFJ_Thresh2*(1+TaxBracketInflation)^25,IRMAA_MFJ_Cost2*(1+SSCOLA)^25,IF(AA25<=IRMAA_MFJ_Thresh3*(1+TaxBracketInflation)^25,IRMAA_MFJ_Cost3*(1+SSCOLA)^25,IF(AA25<=IRMAA_MFJ_Thresh4*(1+TaxBracketInflation)^25,IRMAA_MFJ_Cost4*(1+SSCOLA)^25,IF(AA25<=IRMAA_MFJ_Thresh5*(1+TaxBracketInflation)^25,IRMAA_MFJ_Cost5*(1+SSCOLA)^25,IRMAA_MFJ_Cost6*(1+SSCOLA)^25))))),IF(AA25<=IRMAA_Single_Thresh1*(1+TaxBracketInflation)^25,IRMAA_Single_Cost1*(1+SSCOLA)^25,IF(AA25<=IRMAA_Single_Thresh2*(1+TaxBracketInflation)^25,IRMAA_Single_Cost2*(1+SSCOLA)^25,IF(AA25<=IRMAA_Single_Thresh3*(1+TaxBracketInflation)^25,IRMAA_Single_Cost3*(1+SSCOLA)^25,IF(AA25<=IRMAA_Single_Thresh4*(1+TaxBracketInflation)^25,IRMAA_Single_Cost4*(1+SSCOLA)^25,IF(AA25<=IRMAA_Single_Thresh5*(1+TaxBracketInflation)^25,IRMAA_Single_Cost5*(1+SSCOLA)^25,IRMAA_Single_Cost6*(1+SSCOLA)^25)))))) | AB26: =IF(AB4,IF(AB25<=IRMAA_MFJ_Thresh1*(1+TaxBracketInflation)^26,IRMAA_MFJ_Cost1*(1+SSCOLA)^26,IF(AB25<=IRMAA_MFJ_Thresh2*(1+TaxBracketInflation)^26,IRMAA_MFJ_Cost2*(1+SSCOLA)^26,IF(AB25<=IRMAA_MFJ_Thresh3*(1+TaxBracketInflation)^26,IRMAA_MFJ_Cost3*(1+SSCOLA)^26,IF(AB25<=IRMAA_MFJ_Thresh4*(1+TaxBracketInflation)^26,IRMAA_MFJ_Cost4*(1+SSCOLA)^26,IF(AB25<=IRMAA_MFJ_Thresh5*(1+TaxBracketInflation)^26,IRMAA_MFJ_Cost5*(1+SSCOLA)^26,IRMAA_MFJ_Cost6*(1+SSCOLA)^26))))),IF(AB25<=IRMAA_Single_Thresh1*(1+TaxBracketInflation)^26,IRMAA_Single_Cost1*(1+SSCOLA)^26,IF(AB25<=IRMAA_Single_Thresh2*(1+TaxBracketInflation)^26,IRMAA_Single_Cost2*(1+SSCOLA)^26,IF(AB25<=IRMAA_Single_Thresh3*(1+TaxBracketInflation)^26,IRMAA_Single_Cost3*(1+SSCOLA)^26,IF(AB25<=IRMAA_Single_Thresh4*(1+TaxBracketInflation)^26,IRMAA_Single_Cost4*(1+SSCOLA)^26,IF(AB25<=IRMAA_Single_Thresh5*(1+TaxBracketInflation)^26,IRMAA_Single_Cost5*(1+SSCOLA)^26,IRMAA_Single_Cost6*(1+SSCOLA)^26)))))) | AC26: =IF(AC4,IF(AC25<=IRMAA_MFJ_Thresh1*(1+TaxBracketInflation)^27,IRMAA_MFJ_Cost1*(1+SSCOLA)^27,IF(AC25<=IRMAA_MFJ_Thresh2*(1+TaxBracketInflation)^27,IRMAA_MFJ_Cost2*(1+SSCOLA)^27,IF(AC25<=IRMAA_MFJ_Thresh3*(1+TaxBracketInflation)^27,IRMAA_MFJ_Cost3*(1+SSCOLA)^27,IF(AC25<=IRMAA_MFJ_Thresh4*(1+TaxBracketInflation)^27,IRMAA_MFJ_Cost4*(1+SSCOLA)^27,IF(AC25<=IRMAA_MFJ_Thresh5*(1+TaxBracketInflation)^27,IRMAA_MFJ_Cost5*(1+SSCOLA)^27,IRMAA_MFJ_Cost6*(1+SSCOLA)^27))))),IF(AC25<=IRMAA_Single_Thresh1*(1+TaxBracketInflation)^27,IRMAA_Single_Cost1*(1+SSCOLA)^27,IF(AC25<=IRMAA_Single_Thresh2*(1+TaxBracketInflation)^27,IRMAA_Single_Cost2*(1+SSCOLA)^27,IF(AC25<=IRMAA_Single_Thresh3*(1+TaxBracketInflation)^27,IRMAA_Single_Cost3*(1+SSCOLA)^27,IF(AC25<=IRMAA_Single_Thresh4*(1+TaxBracketInflation)^27,IRMAA_Single_Cost4*(1+SSCOLA)^27,IF(AC25<=IRMAA_Single_Thresh5*(1+TaxBracketInflation)^27,IRMAA_Single_Cost5*(1+SSCOLA)^27,IRMAA_Single_Cost6*(1+SSCOLA)^27)))))) | AD26: =IF(AD4,IF(AD25<=IRMAA_MFJ_Thresh1*(1+TaxBracketInflation)^28,IRMAA_MFJ_Cost1*(1+SSCOLA)^28,IF(AD25<=IRMAA_MFJ_Thresh2*(1+TaxBracketInflation)^28,IRMAA_MFJ_Cost2*(1+SSCOLA)^28,IF(AD25<=IRMAA_MFJ_Thresh3*(1+TaxBracketInflation)^28,IRMAA_MFJ_Cost3*(1+SSCOLA)^28,IF(AD25<=IRMAA_MFJ_Thresh4*(1+TaxBracketInflation)^28,IRMAA_MFJ_Cost4*(1+SSCOLA)^28,IF(AD25<=IRMAA_MFJ_Thresh5*(1+TaxBracketInflation)^28,IRMAA_MFJ_Cost5*(1+SSCOLA)^28,IRMAA_MFJ_Cost6*(1+SSCOLA)^28))))),IF(AD25<=IRMAA_Single_Thresh1*(1+TaxBracketInflation)^28,IRMAA_Single_Cost1*(1+SSCOLA)^28,IF(AD25<=IRMAA_Single_Thresh2*(1+TaxBracketInflation)^28,IRMAA_Single_Cost2*(1+SSCOLA)^28,IF(AD25<=IRMAA_Single_Thresh3*(1+TaxBracketInflation)^28,IRMAA_Single_Cost3*(1+SSCOLA)^28,IF(AD25<=IRMAA_Single_Thresh4*(1+TaxBracketInflation)^28,IRMAA_Single_Cost4*(1+SSCOLA)^28,IF(AD25<=IRMAA_Single_Thresh5*(1+TaxBracketInflation)^28,IRMAA_Single_Cost5*(1+SSCOLA)^28,IRMAA_Single_Cost6*(1+SSCOLA)^28)))))) | AE26: =IF(AE4,IF(AE25<=IRMAA_MFJ_Thresh1*(1+TaxBracketInflation)^29,IRMAA_MFJ_Cost1*(1+SSCOLA)^29,IF(AE25<=IRMAA_MFJ_Thresh2*(1+TaxBracketInflation)^29,IRMAA_MFJ_Cost2*(1+SSCOLA)^29,IF(AE25<=IRMAA_MFJ_Thresh3*(1+TaxBracketInflation)^29,IRMAA_MFJ_Cost3*(1+SSCOLA)^29,IF(AE25<=IRMAA_MFJ_Thresh4*(1+TaxBracketInflation)^29,IRMAA_MFJ_Cost4*(1+SSCOLA)^29,IF(AE25<=IRMAA_MFJ_Thresh5*(1+TaxBracketInflation)^29,IRMAA_MFJ_Cost5*(1+SSCOLA)^29,IRMAA_MFJ_Cost6*(1+SSCOLA)^29))))),IF(AE25<=IRMAA_Single_Thresh1*(1+TaxBracketInflation)^29,IRMAA_Single_Cost1*(1+SSCOLA)^29,IF(AE25<=IRMAA_Single_Thresh2*(1+TaxBracketInflation)^29,IRMAA_Single_Cost2*(1+SSCOLA)^29,IF(AE25<=IRMAA_Single_Thresh3*(1+TaxBracketInflation)^29,IRMAA_Single_Cost3*(1+SSCOLA)^29,IF(AE25<=IRMAA_Single_Thresh4*(1+TaxBracketInflation)^29,IRMAA_Single_Cost4*(1+SSCOLA)^29,IF(AE25<=IRMAA_Single_Thresh5*(1+TaxBracketInflation)^29,IRMAA_Single_Cost5*(1+SSCOLA)^29,IRMAA_Single_Cost6*(1+SSCOLA)^29))))))
